Workbook

Sheet Output values
A1: DATE | B1: Excess GDP | C1: Labor Tightness | D1: Labor SR | E1: Labor Sigmoid | F1: INFL SR | G1: Real Yield | H1: Com Tightness | I1: Com SR
A2: 23559 | B2: ='Excess GDP growth Trend'!F200 -> 0.56666667 | C2: ='Labor Market'!H200 -> 0.43333333 | D2: ='Labor Market'!G200 -> 0.3 | E2: 0.24910941 | F2: =Inflation!L213 -> -0.0047249949 | G2: =Inflation!S212 -> 0.029200452 | H2: =Commodity!F68 -> -0.11798429 | I2: =Commodity!G68 -> -0.033087143
A3: 23590 | B3: ='Excess GDP growth Trend'!F201 -> 0.43333333 | C3: ='Labor Market'!H201 -> 0.46666667 | D3: ='Labor Market'!G201 -> 0.23333333 | E3: 0.21839645 | F3: =Inflation!L214 -> -0.0037268863 | G3: =Inflation!S213 -> 0.0308306 | H3: =Commodity!F69 -> -0.11905143 | I3: =Commodity!G69 -> -0.0273
A4: 23621 | B4: ='Excess GDP growth Trend'!F202 -> 0.43333333 | C4: ='Labor Market'!H202 -> 0.4 | D4: ='Labor Market'!G202 -> 0.2 | E4: 0.2407874 | F4: =Inflation!L215 -> -0.001903472 | G4: =Inflation!S214 -> 0.031186246 | H4: =Commodity!F70 -> -0.11239 | I4: =Commodity!G70 -> -0.014991429
A5: 23651 | B5: ='Excess GDP growth Trend'!F203 -> 0.33333333 | C5: ='Labor Market'!H203 -> 0.33333333 | D5: ='Labor Market'!G203 -> 0 | E5: 0.18379121 | F5: =Inflation!L216 -> 0.0013287924 | G5: =Inflation!S215 -> 0.031103924 | H5: =Commodity!F71 -> -0.11086 | I5: =Commodity!G71 -> -0.010124286
A6: 23682 | B6: ='Excess GDP growth Trend'!F204 -> 0.5 | C6: ='Labor Market'!H204 -> 0.4 | D6: ='Labor Market'!G204 -> 0.033333333 | E6: 0.2407874 | F6: =Inflation!L217 -> 0.00058964751 | G6: =Inflation!S216 -> 0.029101808 | H6: =Commodity!F72 -> -0.10836857 | I6: =Commodity!G72 -> -0.0056271429
A7: 23712 | B7: ='Excess GDP growth Trend'!F205 -> 0.53333333 | C7: ='Labor Market'!H205 -> 0.43333333 | D7: ='Labor Market'!G205 -> 0.033333333 | E7: 0.24910941 | F7: =Inflation!L218 -> 0.0013541392 | G7: =Inflation!S217 -> 0.030396598 | H7: =Commodity!F73 -> -0.10132143 | I7: =Commodity!G73 -> 0.013605714
A8: 23743 | B8: ='Excess GDP growth Trend'!F206 -> 0.63333333 | C8: ='Labor Market'!H206 -> 0.5 | D8: ='Labor Market'!G206 -> 0.16666667 | E8: 0.26427847 | F8: =Inflation!L219 -> 0.00075717284 | G8: =Inflation!S218 -> 0.029749785 | H8: =Commodity!F74 -> -0.087597143 | I8: =Commodity!G74 -> 0.030387143
A9: 23774 | B9: ='Excess GDP growth Trend'!F207 -> 0.43333333 | C9: ='Labor Market'!H207 -> 0.4 | D9: ='Labor Market'!G207 -> 0 | E9: 0.1407874 | F9: =Inflation!L220 -> 0.0025086509 | G9: =Inflation!S219 -> 0.028944635 | H9: =Commodity!F75 -> -0.082105714 | I9: =Commodity!G75 -> 0.036945714
A10: 23802 | B10: ='Excess GDP growth Trend'!F208 -> 0.5 | C10: ='Labor Market'!H208 -> 0.5 | D10: ='Labor Market'!G208 -> 0.066666667 | E10: 0.21393971 | F10: =Inflation!L221 -> 0.0035178775 | G10: =Inflation!S220 -> 0.028187947 | H10: =Commodity!F76 -> -0.077582857 | I10: =Commodity!G76 -> 0.034807143
A11: 23833 | B11: ='Excess GDP growth Trend'!F209 -> 0.43333333 | C11: ='Labor Market'!H209 -> 0.53333333 | D11: ='Labor Market'!G209 -> 0.033333333 | E11: 0.18486989 | F11: =Inflation!L222 -> 0.0029108692 | G11: =Inflation!S221 -> 0.026331907 | H11: =Commodity!F77 -> -0.075132857 | I11: =Commodity!G77 -> 0.035727143
A12: 23863 | B12: ='Excess GDP growth Trend'!F210 -> 0.5 | C12: ='Labor Market'!H210 -> 0.7 | D12: ='Labor Market'!G210 -> 0.3 | E12: 0.18802693 | F12: =Inflation!L223 -> 0.0024849909 | G12: =Inflation!S222 -> 0.026033766 | H12: =Commodity!F78 -> -0.066741429 | I12: =Commodity!G78 -> 0.041627143
A13: 23894 | B13: ='Excess GDP growth Trend'!F211 -> 0.43333333 | C13: ='Labor Market'!H211 -> 0.73333333 | D13: ='Labor Market'!G211 -> 0.23333333 | E13: 0.17304729 | F13: =Inflation!L224 -> -1.7372093e-05 | G13: =Inflation!S223 -> 0.025702956 | H13: =Commodity!F79 -> -0.054305714 | I13: =Commodity!G79 -> 0.047015714
... A743: 46113 | B743: ='Excess GDP growth Trend'!F941 -> -0.033333333 | C743: ='Labor Market'!H941 -> -0.23333333 | D743: ='Labor Market'!G941 -> 0.066666667 | E743: 0.0061841931 | F743: =Inflation!L954 -> 0 | G743: =Inflation!S953 -> 0.012235366 | H743: =Commodity!F809 -> -0.036382857 | I743: =Commodity!G809 -> 0.090114286

Sheet Excess GDP growth Trend
A1: observation_date | B1: UNRATE | C1: UNRATE 3m av | E1: Y diff
A2: 17533 | B2: 3.4
A3: 17564 | B3: 3.8
A4: 17593 | B4: 4 | C4: =AVERAGE(B2:B4) -> 3.7333333
A5: 17624 | B5: 3.9 | C5: =AVERAGE(B3:B5) -> 3.9
A6: 17654 | B6: 3.5 | C6: =AVERAGE(B4:B6) -> 3.8
A7: 17685 | B7: 3.6 | C7: =AVERAGE(B5:B7) -> 3.6666667
A8: 17715 | B8: 3.6 | C8: =AVERAGE(B6:B8) -> 3.5666667
A9: 17746 | B9: 3.9 | C9: =AVERAGE(B7:B9) -> 3.7
A10: 17777 | B10: 3.8 | C10: =AVERAGE(B8:B10) -> 3.7666667
A11: 17807 | B11: 3.7 | C11: =AVERAGE(B9:B11) -> 3.8
A12: 17838 | B12: 3.8 | C12: =AVERAGE(B10:B12) -> 3.7666667
A13: 17868 | B13: 4 | C13: =AVERAGE(B11:B13) -> 3.8333333
A14: 17899 | B14: 4.3 | C14: =AVERAGE(B12:B14) -> 4.0333333
A15: 17930 | B15: 4.7 | C15: =AVERAGE(B13:B15) -> 4.3333333
A16: 17958 | B16: 5 | C16: =AVERAGE(B14:B16) -> 4.6666667 | E16: =C4-C16 -> -0.93333333
A17: 17989 | B17: 5.3 | C17: =AVERAGE(B15:B17) -> 5 | E17: =C5-C17 -> -1.1
A18: 18019 | B18: 6.1 | C18: =AVERAGE(B16:B18) -> 5.4666667 | E18: =C6-C18 -> -1.6666667
A19: 18050 | B19: 6.2 | C19: =AVERAGE(B17:B19) -> 5.8666667 | E19: =C7-C19 -> -2.2
A20: 18080 | B20: 6.7 | C20: =AVERAGE(B18:B20) -> 6.3333333 | E20: =C8-C20 -> -2.7666667
A21: 18111 | B21: 6.8 | C21: =AVERAGE(B19:B21) -> 6.5666667 | E21: =C9-C21 -> -2.8666667
A22: 18142 | B22: 6.6 | C22: =AVERAGE(B20:B22) -> 6.7 | E22: =C10-C22 -> -2.9333333
A23: 18172 | B23: 7.9 | C23: =AVERAGE(B21:B23) -> 7.1 | E23: =C11-C23 -> -3.3
A24: 18203 | B24: 6.4 | C24: =AVERAGE(B22:B24) -> 6.9666667 | E24: =C12-C24 -> -3.2
A25: 18233 | B25: 6.6 | C25: =AVERAGE(B23:B25) -> 6.9666667 | E25: =C13-C25 -> -3.1333333
A26: 18264 | B26: 6.5 | C26: =AVERAGE(B24:B26) -> 6.5 | E26: =C14-C26 -> -2.4666667
A27: 18295 | B27: 6.4 | C27: =AVERAGE(B25:B27) -> 6.5 | E27: =C15-C27 -> -2.1666667
... A75: 19756 | B75: 5.2 | C75: =AVERAGE(B73:B75) -> 4.8666667 | E75: =C63-C75 -> -2.1333333
A76: 19784 | B76: 5.7 | C76: =AVERAGE(B74:B76) -> 5.2666667 | E76: =C64-C76 -> -2.5666667 | F76: =E76-MEDIAN(E16:E76) -> -2.9
A77: 19815 | B77: 5.9 | C77: =AVERAGE(B75:B77) -> 5.6 | E77: =C65-C77 -> -2.9666667 | F77: =E77-MEDIAN(E17:E77) -> -3.3
A78: 19845 | B78: 5.9 | C78: =AVERAGE(B76:B78) -> 5.8333333 | E78: =C66-C78 -> -3.2333333 | F78: =E78-MEDIAN(E18:E78) -> -3.5666667
A79: 19876 | B79: 5.6 | C79: =AVERAGE(B77:B79) -> 5.8 | E79: =C67-C79 -> -3.2333333 | F79: =E79-MEDIAN(E19:E79) -> -3.5666667
A80: 19906 | B80: 5.8 | C80: =AVERAGE(B78:B80) -> 5.7666667 | E80: =C68-C80 -> -3.2333333 | F80: =E80-MEDIAN(E20:E80) -> -3.5666667
A81: 19937 | B81: 6 | C81: =AVERAGE(B79:B81) -> 5.8 | E81: =C69-C81 -> -3.2 | F81: =E81-MEDIAN(E21:E81) -> -3.5333333
A82: 19968 | B82: 6.1 | C82: =AVERAGE(B80:B82) -> 5.9666667 | E82: =C70-C82 -> -3.2333333 | F82: =E82-MEDIAN(E22:E82) -> -3.5666667
A83: 19998 | B83: 5.7 | C83: =AVERAGE(B81:B83) -> 5.9333333 | E83: =C71-C83 -> -3.0333333 | F83: =E83-MEDIAN(E23:E83) -> -3.3666667
A84: 20029 | B84: 5.3 | C84: =AVERAGE(B82:B84) -> 5.7 | E84: =C72-C84 -> -2.5333333 | F84: =E84-MEDIAN(E24:E84) -> -2.8666667
A85: 20059 | B85: 5 | C85: =AVERAGE(B83:B85) -> 5.3333333 | E85: =C73-C85 -> -1.6333333 | F85: =E85-MEDIAN(E25:E85) -> -1.9666667
A86: 20090 | B86: 4.9 | C86: =AVERAGE(B84:B86) -> 5.0666667 | E86: =C74-C86 -> -0.76666667 | F86: =E86-MEDIAN(E26:E86) -> -1.1
A87: 20121 | B87: 4.7 | C87: =AVERAGE(B85:B87) -> 4.8666667 | E87: =C75-C87 -> 0 | F87: =E87-MEDIAN(E27:E87) -> -0.33333333
...

Sheet Labor Market
A1: observation_date | B1: UNRATE | C1: UNRATE 3m av | D1: 10 year med | E1: avg med/mean | F1: SR alternative | G1: SR | H1: Tightenss | I1: Delta Tightness | K1: Bottom Sigmoid | L1: Top sigmoid | M1: Neg change | N1: Pos change | Q1: 2 year max dist | R1: 2 year min dist | S1: change pos | T1: change neg
A2: 17533 | B2: 3.4 | K2: 1
A3: 17564 | B3: 3.8
A4: 17593 | B4: 4 | C4: =AVERAGE(B2:B4) -> 3.7333333
A5: 17624 | B5: 3.9 | C5: =AVERAGE(B3:B5) -> 3.9
A6: 17654 | B6: 3.5 | C6: =AVERAGE(B4:B6) -> 3.8
A7: 17685 | B7: 3.6 | C7: =AVERAGE(B5:B7) -> 3.6666667 | E7: =AVERAGE(F7:G7) -> 0.13333333 | F7: =MEDIAN(B2:B4)-MEDIAN(B5:B7) -> 0.2 | G7: =C4-C7 -> 0.066666667
A8: 17715 | B8: 3.6 | C8: =AVERAGE(B6:B8) -> 3.5666667 | E8: =AVERAGE(F8:G8) -> 0.31666667 | F8: =MEDIAN(B3:B5)-MEDIAN(B6:B8) -> 0.3 | G8: =C5-C8 -> 0.33333333
A9: 17746 | B9: 3.9 | C9: =AVERAGE(B7:B9) -> 3.7 | E9: =AVERAGE(F9:G9) -> 0.2 | F9: =MEDIAN(B4:B6)-MEDIAN(B7:B9) -> 0.3 | G9: =C6-C9 -> 0.1
A10: 17777 | B10: 3.8 | C10: =AVERAGE(B8:B10) -> 3.7666667 | E10: =AVERAGE(F10:G10) -> -0.15 | F10: =MEDIAN(B5:B7)-MEDIAN(B8:B10) -> -0.2 | G10: =C7-C10 -> -0.1
A11: 17807 | B11: 3.7 | C11: =AVERAGE(B9:B11) -> 3.8 | E11: =AVERAGE(F11:G11) -> -0.21666667 | F11: =MEDIAN(B6:B8)-MEDIAN(B9:B11) -> -0.2 | G11: =C8-C11 -> -0.23333333
A12: 17838 | B12: 3.8 | C12: =AVERAGE(B10:B12) -> 3.7666667 | E12: =AVERAGE(F12:G12) -> -0.13333333 | F12: =MEDIAN(B7:B9)-MEDIAN(B10:B12) -> -0.2 | G12: =C9-C12 -> -0.066666667
A13: 17868 | B13: 4 | C13: =AVERAGE(B11:B13) -> 3.8333333 | E13: =AVERAGE(F13:G13) -> -0.033333333 | F13: =MEDIAN(B8:B10)-MEDIAN(B11:B13) -> 0 | G13: =C10-C13 -> -0.066666667
A14: 17899 | B14: 4.3 | C14: =AVERAGE(B12:B14) -> 4.0333333 | E14: =AVERAGE(F14:G14) -> -0.21666667 | F14: =MEDIAN(B9:B11)-MEDIAN(B12:B14) -> -0.2 | G14: =C11-C14 -> -0.23333333
A15: 17930 | B15: 4.7 | C15: =AVERAGE(B13:B15) -> 4.3333333 | E15: =AVERAGE(F15:G15) -> -0.53333333 | F15: =MEDIAN(B10:B12)-MEDIAN(B13:B15) -> -0.5 | G15: =C12-C15 -> -0.56666667
A16: 17958 | B16: 5 | C16: =AVERAGE(B14:B16) -> 4.6666667 | E16: =AVERAGE(F16:G16) -> -0.86666667 | F16: =MEDIAN(B11:B13)-MEDIAN(B14:B16) -> -0.9 | G16: =C13-C16 -> -0.83333333
A17: 17989 | B17: 5.3 | C17: =AVERAGE(B15:B17) -> 5 | E17: =AVERAGE(F17:G17) -> -0.98333333 | F17: =MEDIAN(B12:B14)-MEDIAN(B15:B17) -> -1 | G17: =C14-C17 -> -0.96666667
A18: 18019 | B18: 6.1 | C18: =AVERAGE(B16:B18) -> 5.4666667 | E18: =AVERAGE(F18:G18) -> -1.0666667 | F18: =MEDIAN(B13:B15)-MEDIAN(B16:B18) -> -1 | G18: =C15-C18 -> -1.1333333
A19: 18050 | B19: 6.2 | C19: =AVERAGE(B17:B19) -> 5.8666667 | E19: =AVERAGE(F19:G19) -> -1.3 | F19: =MEDIAN(B14:B16)-MEDIAN(B17:B19) -> -1.4 | G19: =C16-C19 -> -1.2
A20: 18080 | B20: 6.7 | C20: =AVERAGE(B18:B20) -> 6.3333333 | E20: =AVERAGE(F20:G20) -> -1.2666667 | F20: =MEDIAN(B15:B17)-MEDIAN(B18:B20) -> -1.2 | G20: =C17-C20 -> -1.3333333 | Q20: alt metric
A21: 18111 | B21: 6.8 | C21: =AVERAGE(B19:B21) -> 6.5666667 | E21: =AVERAGE(F21:G21) -> -1.25 | F21: =MEDIAN(B16:B18)-MEDIAN(B19:B21) -> -1.4 | G21: =C18-C21 -> -1.1 | Q21: 0.5
A22: 18142 | B22: 6.6 | C22: =AVERAGE(B20:B22) -> 6.7 | E22: =AVERAGE(F22:G22) -> -0.71666667 | F22: =MEDIAN(B17:B19)-MEDIAN(B20:B22) -> -0.6 | G22: =C19-C22 -> -0.83333333
A23: 18172 | B23: 7.9 | C23: =AVERAGE(B21:B23) -> 7.1 | E23: =AVERAGE(F23:G23) -> -0.68333333 | F23: =MEDIAN(B18:B20)-MEDIAN(B21:B23) -> -0.6 | G23: =C20-C23 -> -0.76666667
A24: 18203 | B24: 6.4 | C24: =AVERAGE(B22:B24) -> 6.9666667 | E24: =AVERAGE(F24:G24) -> -0.15 | F24: =MEDIAN(B19:B21)-MEDIAN(B22:B24) -> 0.1 | G24: =C21-C24 -> -0.4
A25: 18233 | B25: 6.6 | C25: =AVERAGE(B23:B25) -> 6.9666667 | E25: =AVERAGE(F25:G25) -> -0.083333333 | F25: =MEDIAN(B20:B22)-MEDIAN(B23:B25) -> 0.1 | G25: =C22-C25 -> -0.26666667
A26: 18264 | B26: 6.5 | C26: =AVERAGE(B24:B26) -> 6.5 | E26: =AVERAGE(F26:G26) -> 0.45 | F26: =MEDIAN(B21:B23)-MEDIAN(B24:B26) -> 0.3 | G26: =C23-C26 -> 0.6 | Q26: =MAX(B2:B26)-B26 -> 1.4 | R26: =B26-MIN(B2:B26)-B26 -> -3.4 | S26: =MAX(F26,0) -> 0.3 | T26: =MIN(F26,0) -> 0 | U26: =T26/(1+EXP(-Q26*Q$21)) -> 0 | V26: =S26/(1+EXP(R26*Q$21)) -> 0.25366042 | W26: =V26+U26 -> 0.25366042
A27: 18295 | B27: 6.4 | C27: =AVERAGE(B25:B27) -> 6.5 | E27: =AVERAGE(F27:G27) -> 0.28333333 | F27: =MEDIAN(B22:B24)-MEDIAN(B25:B27) -> 0.1 | G27: =C24-C27 -> 0.46666667 | Q27: =MAX(B3:B27)-B27 -> 1.5 | R27: =B27-MIN(B3:B27)-B27 -> -3.5 | S27: =MAX(F27,0) -> 0.1 | T27: =MIN(F27,0) -> 0 | U27: =T27/(1+EXP(-Q27*Q$21)) -> 0 | V27: =S27/(1+EXP(R27*Q$21)) -> 0.08519528 | W27: =V27+U27 -> 0.08519528
A28: 18323 | B28: 6.3 | C28: =AVERAGE(B26:B28) -> 6.4 | E28: =AVERAGE(F28:G28) -> 0.38333333 | F28: =MEDIAN(B23:B25)-MEDIAN(B26:B28) -> 0.2 | G28: =C25-C28 -> 0.56666667 | Q28: =MAX(B4:B28)-B28 -> 1.6 | R28: =B28-MIN(B4:B28)-B28 -> -3.5 | S28: =MAX(F28,0) -> 0.2 | T28: =MIN(F28,0) -> 0 | U28: =T28/(1+EXP(-Q28*Q$21)) -> 0 | V28: =S28/(1+EXP(R28*Q$21)) -> 0.17039056 | W28: =V28+U28 -> 0.17039056
A29: 18354 | B29: 5.8 | C29: =AVERAGE(B27:B29) -> 6.1666667 | E29: =AVERAGE(F29:G29) -> 0.26666667 | F29: =MEDIAN(B24:B26)-MEDIAN(B27:B29) -> 0.2 | G29: =C26-C29 -> 0.33333333 | Q29: =MAX(B5:B29)-B29 -> 2.1 | R29: =B29-MIN(B5:B29)-B29 -> -3.5 | S29: =MAX(F29,0) -> 0.2 | T29: =MIN(F29,0) -> 0 | U29: =T29/(1+EXP(-Q29*Q$21)) -> 0 | V29: =S29/(1+EXP(R29*Q$21)) -> 0.17039056 | W29: =V29+U29 -> 0.17039056
A30: 18384 | B30: 5.5 | C30: =AVERAGE(B28:B30) -> 5.8666667 | E30: =AVERAGE(F30:G30) -> 0.66666667 | F30: =MEDIAN(B25:B27)-MEDIAN(B28:B30) -> 0.7 | G30: =C27-C30 -> 0.63333333 | Q30: =MAX(B6:B30)-B30 -> 2.4 | R30: =B30-MIN(B6:B30)-B30 -> -3.5 | S30: =MAX(F30,0) -> 0.7 | T30: =MIN(F30,0) -> 0 | U30: =T30/(1+EXP(-Q30*Q$21)) -> 0 | V30: =S30/(1+EXP(R30*Q$21)) -> 0.59636696 | W30: =V30+U30 -> 0.59636696
A31: 18415 | B31: 5.4 | C31: =AVERAGE(B29:B31) -> 5.5666667 | E31: =AVERAGE(F31:G31) -> 0.86666667 | F31: =MEDIAN(B26:B28)-MEDIAN(B29:B31) -> 0.9 | G31: =C28-C31 -> 0.83333333 | Q31: =MAX(B7:B31)-B31 -> 2.5 | R31: =B31-MIN(B7:B31)-B31 -> -3.6 | S31: =MAX(F31,0) -> 0.9 | T31: =MIN(F31,0) -> 0 | U31: =T31/(1+EXP(-Q31*Q$21)) -> 0 | V31: =S31/(1+EXP(R31*Q$21)) -> 0.77233404 | W31: =V31+U31 -> 0.77233404
A32: 18445 | B32: 5 | C32: =AVERAGE(B30:B32) -> 5.3 | E32: =AVERAGE(F32:G32) -> 0.88333333 | F32: =MEDIAN(B27:B29)-MEDIAN(B30:B32) -> 0.9 | G32: =C29-C32 -> 0.86666667 | Q32: =MAX(B8:B32)-B32 -> 2.9 | R32: =B32-MIN(B8:B32)-B32 -> -3.6 | S32: =MAX(F32,0) -> 0.9 | T32: =MIN(F32,0) -> 0 | U32: =T32/(1+EXP(-Q32*Q$21)) -> 0 | V32: =S32/(1+EXP(R32*Q$21)) -> 0.77233404 | W32: =V32+U32 -> 0.77233404
A33: 18476 | B33: 4.5 | C33: =AVERAGE(B31:B33) -> 4.9666667 | E33: =AVERAGE(F33:G33) -> 0.85 | F33: =MEDIAN(B28:B30)-MEDIAN(B31:B33) -> 0.8 | G33: =C30-C33 -> 0.9 | Q33: =MAX(B9:B33)-B33 -> 3.4 | R33: =B33-MIN(B9:B33)-B33 -> -3.7 | S33: =MAX(F33,0) -> 0.8 | T33: =MIN(F33,0) -> 0 | U33: =T33/(1+EXP(-Q33*Q$21)) -> 0 | V33: =S33/(1+EXP(R33*Q$21)) -> 0.69130168 | W33: =V33+U33 -> 0.69130168
A34: 18507 | B34: 4.4 | C34: =AVERAGE(B32:B34) -> 4.6333333 | E34: =AVERAGE(F34:G34) -> 0.96666667 | F34: =MEDIAN(B29:B31)-MEDIAN(B32:B34) -> 1 | G34: =C31-C34 -> 0.93333333 | Q34: =MAX(B10:B34)-B34 -> 3.5 | R34: =B34-MIN(B10:B34)-B34 -> -3.7 | S34: =MAX(F34,0) -> 1 | T34: =MIN(F34,0) -> 0 | U34: =T34/(1+EXP(-Q34*Q$21)) -> 0 | V34: =S34/(1+EXP(R34*Q$21)) -> 0.8641271 | W34: =V34+U34 -> 0.8641271
A35: 18537 | B35: 4.2 | C35: =AVERAGE(B33:B35) -> 4.3666667 | E35: =AVERAGE(F35:G35) -> 0.96666667 | F35: =MEDIAN(B30:B32)-MEDIAN(B33:B35) -> 1 | G35: =C32-C35 -> 0.93333333 | Q35: =MAX(B11:B35)-B35 -> 3.7 | R35: =B35-MIN(B11:B35)-B35 -> -3.7 | S35: =MAX(F35,0) -> 1 | T35: =MIN(F35,0) -> 0 | U35: =T35/(1+EXP(-Q35*Q$21)) -> 0 | V35: =S35/(1+EXP(R35*Q$21)) -> 0.8641271 | W35: =V35+U35 -> 0.8641271
A36: 18568 | B36: 4.2 | C36: =AVERAGE(B34:B36) -> 4.2666667 | E36: =AVERAGE(F36:G36) -> 0.75 | F36: =MEDIAN(B31:B33)-MEDIAN(B34:B36) -> 0.8 | G36: =C33-C36 -> 0.7 | Q36: =MAX(B12:B36)-B36 -> 3.7 | R36: =B36-MIN(B12:B36)-B36 -> -3.8 | S36: =MAX(F36,0) -> 0.8 | T36: =MIN(F36,0) -> 0 | U36: =T36/(1+EXP(-Q36*Q$21)) -> 0 | V36: =S36/(1+EXP(R36*Q$21)) -> 0.69591322 | W36: =V36+U36 -> 0.69591322
A37: 18598 | B37: 4.3 | C37: =AVERAGE(B35:B37) -> 4.2333333 | E37: =AVERAGE(F37:G37) -> 0.35 | F37: =MEDIAN(B32:B34)-MEDIAN(B35:B37) -> 0.3 | G37: =C34-C37 -> 0.4 | Q37: =MAX(B13:B37)-B37 -> 3.6 | R37: =B37-MIN(B13:B37)-B37 -> -4 | S37: =MAX(F37,0) -> 0.3 | T37: =MIN(F37,0) -> 0 | U37: =T37/(1+EXP(-Q37*Q$21)) -> 0 | V37: =S37/(1+EXP(R37*Q$21)) -> 0.26423912 | W37: =V37+U37 -> 0.26423912
... A121: 21155 | B121: 5.2 | C121: =AVERAGE(B119:B121) -> 4.9333333 | E121: =AVERAGE(F121:G121) -> -0.8 | F121: =MEDIAN(B116:B118)-MEDIAN(B119:B121) -> -0.9 | G121: =C118-C121 -> -0.7 | Q121: =MAX(B97:B121)-B121 -> 0 | R121: =B121-MIN(B97:B121)-B121 -> -3.7 | S121: =MAX(F121,0) -> 0 | T121: =MIN(F121,0) -> -0.9 | U121: =T121/(1+EXP(-Q121*Q$21)) -> -0.45 | V121: =S121/(1+EXP(R121*Q$21)) -> 0 | W121: =V121+U121 -> -0.45
A122: 21186 | B122: 5.8 | C122: =AVERAGE(B120:B122) -> 5.3666667 | D122: =MEDIAN(B2:B122) -> 4.2 | E122: =AVERAGE(F122:G122) -> -0.91666667 | F122: =MEDIAN(B117:B119)-MEDIAN(B120:B122) -> -0.8 | G122: =C119-C122 -> -1.0333333 | H122: =D122-C122 -> -1.1666667 | K122: =1/(1+EXP(H122*K$2)) -> 0.76254197 | L122: =1-K122 -> 0.23745803 | Q122: =MAX(B98:B122)-B122 -> 0 | R122: =B122-MIN(B98:B122)-B122 -> -3.7 | S122: =MAX(F122,0) -> 0 | T122: =MIN(F122,0) -> -0.8 | U122: =T122/(1+EXP(-Q122*Q$21)) -> -0.4 | V122: =S122/(1+EXP(R122*Q$21)) -> 0 | W122: =V122+U122 -> -0.4
A123: 21217 | B123: 6.4 | C123: =AVERAGE(B121:B123) -> 5.8 | D123: =MEDIAN(B3:B123) -> 4.2 | E123: =AVERAGE(F123:G123) -> -1.2166667 | F123: =MEDIAN(B118:B120)-MEDIAN(B121:B123) -> -1.3 | G123: =C120-C123 -> -1.1333333 | H123: =D123-C123 -> -1.6 | K123: =1/(1+EXP(H123*K$2)) -> 0.83201839 | L123: =1-K123 -> 0.16798161 | Q123: =MAX(B99:B123)-B123 -> 0 | R123: =B123-MIN(B99:B123)-B123 -> -3.7 | S123: =MAX(F123,0) -> 0 | T123: =MIN(F123,0) -> -1.3 | U123: =T123/(1+EXP(-Q123*Q$21)) -> -0.65 | V123: =S123/(1+EXP(R123*Q$21)) -> 0 | W123: =V123+U123 -> -0.65
...

Sheet Inflation
A1: observation_date | B1: CPIAUCSL | C1: CPILFESL | D1: TB3MS | E1: DGS10 | G1: CPI YoY | H1: Core YoY | I1: CPI 6m6m | J1: Core 6m6m | K1: avg | N1: adj | O1: CPI YoY | P1: Core YoY | Q1: CPI 6m6m | R1: Core 6m6m | S1: avg
A2: 17168 | B2: 21.48 | D2: 0.38
A3: 17199 | B3: 21.62 | D3: 0.38
A4: 17227 | B4: 22 | D4: 0.38
A5: 17258 | B5: 22 | D5: 0.38
A6: 17288 | B6: 21.95 | D6: 0.38
A7: 17319 | B7: 22.08 | D7: 0.38
A8: 17349 | B8: 22.23 | D8: 0.66
A9: 17380 | B9: 22.4 | D9: 0.75
A10: 17411 | B10: 22.84 | D10: 0.8
A11: 17441 | B11: 22.91 | D11: 0.85
A12: 17472 | B12: 23.06 | D12: 0.92
A13: 17502 | B13: 23.41 | D13: 0.95
... A121: 20790 | B121: 27.63 | D121: 3.21
A122: 20821 | B122: 27.67 | C122: 28.5 | D122: 3.11
A123: 20852 | B123: 27.8 | C123: 28.6 | D123: 3.1
A124: 20880 | B124: 27.86 | C124: 28.7 | D124: 3.08
A125: 20911 | B125: 27.93 | C125: 28.8 | D125: 3.07
A126: 20941 | B126: 28 | C126: 28.8 | D126: 3.06
A127: 20972 | B127: 28.11 | C127: 28.9 | D127: 3.29
A128: 21002 | B128: 28.19 | C128: 29 | D128: 3.16
A129: 21033 | B129: 28.28 | C129: 29 | D129: 3.37
A130: 21064 | B130: 28.32 | C130: 29.1 | D130: 3.53
A131: 21094 | B131: 28.32 | C131: 29.2 | D131: 3.58
A132: 21125 | B132: 28.41 | C132: 29.3 | D132: 3.31
A133: 21155 | B133: 28.47 | C133: 29.3 | D133: 3.04
A134: 21186 | B134: 28.64 | C134: 29.3 | D134: 2.44 | G134: =B134/B122-1 -> 0.035056017 | H134: =C134/C122-1 -> 0.028070175 | I134: =(AVERAGE(B129:B134)/AVERAGE(B123:B128))^2 -1 -> 0.030607724 | J134: =(AVERAGE(C129:C134)/AVERAGE(C123:C128))^2 -1 -> 0.027970679 | K134: =AVERAGE(G134:J134) -> 0.030426149
A135: 21217 | B135: 28.7 | C135: 29.4 | D135: 1.53 | G135: =B135/B123-1 -> 0.032374101 | H135: =C135/C123-1 -> 0.027972028 | I135: =(AVERAGE(B130:B135)/AVERAGE(B124:B129))^2 -1 -> 0.029796426 | J135: =(AVERAGE(C130:C135)/AVERAGE(C124:C129))^2 -1 -> 0.027905637 | K135: =AVERAGE(G135:J135) -> 0.029512048
A136: 21245 | B136: 28.87 | C136: 29.5 | D136: 1.3 | G136: =B136/B124-1 -> 0.036252692 | H136: =C136/C124-1 -> 0.027874564 | I136: =(AVERAGE(B131:B136)/AVERAGE(B125:B130))^2 -1 -> 0.030796817 | J136: =(AVERAGE(C131:C136)/AVERAGE(C125:C130))^2 -1 -> 0.027840897 | K136: =AVERAGE(G136:J136) -> 0.030691243
A137: 21276 | B137: 28.94 | C137: 29.5 | D137: 1.13 | G137: =B137/B125-1 -> 0.036161833 | H137: =C137/C125-1 -> 0.024305556 | I137: =(AVERAGE(B132:B137)/AVERAGE(B126:B131))^2 -1 -> 0.03348695 | J137: =(AVERAGE(C132:C137)/AVERAGE(C126:C131))^2 -1 -> 0.026611507 | K137: =AVERAGE(G137:J137) -> 0.030141462
A138: 21306 | B138: 28.94 | C138: 29.5 | D138: 0.91 | G138: =B138/B126-1 -> 0.033571429 | H138: =C138/C126-1 -> 0.024305556 | I138: =(AVERAGE(B133:B138)/AVERAGE(B127:B132))^2 -1 -> 0.034844129 | J138: =(AVERAGE(C133:C138)/AVERAGE(C127:C132))^2 -1 -> 0.023053998 | K138: =AVERAGE(G138:J138) -> 0.028943778
A139: 21337 | B139: 28.91 | C139: 29.6 | D139: 0.83 | G139: =B139/B127-1 -> 0.028459623 | H139: =C139/C127-1 -> 0.024221453 | I139: =(AVERAGE(B134:B139)/AVERAGE(B128:B133))^2 -1 -> 0.035727383 | J139: =(AVERAGE(C134:C139)/AVERAGE(C128:C133))^2 -1 -> 0.021844713 | K139: =AVERAGE(G139:J139) -> 0.027563293
A140: 21367 | B140: 28.89 | C140: 29.6 | D140: 0.91 | G140: =B140/B128-1 -> 0.024831501 | H140: =C140/C128-1 -> 0.020689655 | I140: =(AVERAGE(B135:B140)/AVERAGE(B129:B134))^2 -1 -> 0.033245293 | J140: =(AVERAGE(C135:C140)/AVERAGE(C129:C134))^2 -1 -> 0.021807106 | K140: =AVERAGE(G140:J140) -> 0.025143389 | L140: =K140-K137 -> -0.0049980729
A141: 21398 | B141: 28.94 | C141: 29.6 | D141: 1.69 | G141: =B141/B129-1 -> 0.023338048 | H141: =C141/C129-1 -> 0.020689655 | I141: =(AVERAGE(B136:B141)/AVERAGE(B130:B135))^2 -1 -> 0.031022374 | J141: =(AVERAGE(C136:C141)/AVERAGE(C130:C135))^2 -1 -> 0.01945591 | K141: =AVERAGE(G141:J141) -> 0.023626497 | L141: =K141-K138 -> -0.0053172808
A142: 21429 | B142: 28.91 | C142: 29.7 | D142: 2.44 | G142: =B142/B130-1 -> 0.020833333 | H142: =C142/C130-1 -> 0.020618557 | I142: =(AVERAGE(B137:B142)/AVERAGE(B131:B136))^2 -1 -> 0.024888981 | J142: =(AVERAGE(C137:C142)/AVERAGE(C131:C136))^2 -1 -> 0.017118091 | K142: =AVERAGE(G142:J142) -> 0.020864741 | L142: =K142-K139 -> -0.0066985526
A143: 21459 | B143: 28.91 | C143: 29.7 | D143: 2.63 | G143: =B143/B131-1 -> 0.020833333 | H143: =C143/C131-1 -> 0.017123288 | I143: =(AVERAGE(B138:B143)/AVERAGE(B132:B137))^2 -1 -> 0.01716306 | J143: =(AVERAGE(C138:C143)/AVERAGE(C132:C137))^2 -1 -> 0.015945079 | K143: =AVERAGE(G143:J143) -> 0.01776619 | L143: =K143-K140 -> -0.0073771988
A144: 21490 | B144: 28.95 | C144: 29.8 | D144: 2.67 | G144: =B144/B132-1 -> 0.019007392 | H144: =C144/C132-1 -> 0.017064846 | I144: =(AVERAGE(B139:B144)/AVERAGE(B133:B138))^2 -1 -> 0.011040972 | J144: =(AVERAGE(C139:C144)/AVERAGE(C133:C138))^2 -1 -> 0.017069393 | K144: =AVERAGE(G144:J144) -> 0.016045651 | L144: =K144-K141 -> -0.0075808462
A145: 21520 | B145: 28.97 | C145: 29.9 | D145: 2.77 | G145: =B145/B133-1 -> 0.017562346 | H145: =C145/C133-1 -> 0.020477816 | I145: =(AVERAGE(B140:B145)/AVERAGE(B134:B139))^2 -1 -> 0.0066004511 | J145: =(AVERAGE(C140:C145)/AVERAGE(C134:C139))^2 -1 -> 0.017040307 | K145: =AVERAGE(G145:J145) -> 0.01542023 | L145: =K145-K142 -> -0.0054445106
A146: 21551 | B146: 29.01 | C146: 29.9 | D146: 2.82 | G146: =B146/B134-1 -> 0.012918994 | H146: =C146/C134-1 -> 0.020477816 | I146: =(AVERAGE(B141:B146)/AVERAGE(B135:B140))^2 -1 -> 0.0050858151 | J146: =(AVERAGE(C141:C146)/AVERAGE(C135:C140))^2 -1 -> 0.01701132 | K146: =AVERAGE(G146:J146) -> 0.013873486 | L146: =K146-K143 -> -0.0038927038
A147: 21582 | B147: 29 | C147: 29.9 | D147: 2.7 | G147: =B147/B135-1 -> 0.010452962 | H147: =C147/C135-1 -> 0.017006803 | I147: =(AVERAGE(B142:B147)/AVERAGE(B136:B141))^2 -1 -> 0.0029995368 | J147: =(AVERAGE(C142:C147)/AVERAGE(C136:C141))^2 -1 -> 0.018129942 | K147: =AVERAGE(G147:J147) -> 0.012147311 | L147: =K147-K144 -> -0.0038983398
...

Sheet Commodity
A1: observation_date | B1: WPSID62_PCEPILFE
A2: 21551 | B2: 2.03858
A3: 21582 | B3: 2.02411
A4: 21610 | B4: 2.0282
A5: 21641 | B5: 2.03597
A6: 21671 | B6: 2.02066
A7: 21702 | B7: 2.00192
A8: 21732 | B8: 1.97805
A9: 21763 | B9: 1.95579
A10: 21794 | B10: 1.9634
A11: 21824 | B11: 1.94735
A12: 21855 | B12: 1.93111
A13: 21885 | B13: 1.91554
... A61: 23346 | B61: 1.76111
A62: 23377 | B62: 1.78262 | D62: =MEDIAN(B2:B62) -> 1.87869 | E62: =AVERAGE(B56:B62) -> 1.7937929 | F62: =E62-D62 -> -0.084897143
A63: 23408 | B63: 1.75533 | D63: =MEDIAN(B3:B63) -> 1.87771 | E63: =AVERAGE(B57:B63) -> 1.7859586 | F63: =E63-D63 -> -0.091751429
A64: 23437 | B64: 1.75962 | D64: =MEDIAN(B4:B64) -> 1.87723 | E64: =AVERAGE(B58:B64) -> 1.7798314 | F64: =E64-D64 -> -0.097398571
A65: 23468 | B65: 1.75805 | D65: =MEDIAN(B5:B65) -> 1.87554 | E65: =AVERAGE(B59:B65) -> 1.7748043 | F65: =E65-D65 -> -0.10073571
A66: 23498 | B66: 1.75063 | D66: =MEDIAN(B6:B66) -> 1.87117 | E66: =AVERAGE(B60:B66) -> 1.7684286 | F66: =E66-D66 -> -0.10274143
A67: 23529 | B67: 1.72557 | D67: =MEDIAN(B7:B67) -> 1.87106 | E67: =AVERAGE(B61:B67) -> 1.7561329 | F67: =E67-D67 -> -0.11492714
A68: 23559 | B68: 1.73572 | D68: =MEDIAN(B8:B68) -> 1.87049 | E68: =AVERAGE(B62:B68) -> 1.7525057 | F68: =E68-D68 -> -0.11798429 | G68: =F68-F62 -> -0.033087143
A69: 23590 | B69: 1.74533 | D69: =MEDIAN(B9:B69) -> 1.86623 | E69: =AVERAGE(B63:B69) -> 1.7471786 | F69: =E69-D69 -> -0.11905143 | G69: =F69-F63 -> -0.0273
A70: 23621 | B70: 1.78614 | D70: =MEDIAN(B10:B70) -> 1.86397 | E70: =AVERAGE(B64:B70) -> 1.75158 | F70: =E70-D70 -> -0.11239 | G70: =F70-F64 -> -0.014991429
A71: 23651 | B71: 1.7676 | D71: =MEDIAN(B11:B71) -> 1.86358 | E71: =AVERAGE(B65:B71) -> 1.75272 | F71: =E71-D71 -> -0.11086 | G71: =F71-F65 -> -0.010124286
A72: 23682 | B72: 1.77101 | D72: =MEDIAN(B12:B72) -> 1.86294 | E72: =AVERAGE(B66:B72) -> 1.7545714 | F72: =E72-D72 -> -0.10836857 | G72: =F72-F66 -> -0.0056271429
A73: 23712 | B73: 1.76258 | D73: =MEDIAN(B13:B73) -> 1.8576 | E73: =AVERAGE(B67:B73) -> 1.7562786 | F73: =E73-D73 -> -0.10132143 | G73: =F73-F67 -> 0.013605714
A74: 23743 | B74: 1.74247 | D74: =MEDIAN(B14:B74) -> 1.84629 | E74: =AVERAGE(B68:B74) -> 1.7586929 | F74: =E74-D74 -> -0.087597143 | G74: =F74-F68 -> 0.030387143
A75: 23774 | B75: 1.76401 | D75: =MEDIAN(B15:B75) -> 1.84484 | E75: =AVERAGE(B69:B75) -> 1.7627343 | F75: =E75-D75 -> -0.082105714 | G75: =F75-F69 -> 0.036945714
A76: 23802 | B76: 1.76887 | D76: =MEDIAN(B16:B76) -> 1.84368 | E76: =AVERAGE(B70:B76) -> 1.7660971 | F76: =E76-D76 -> -0.077582857 | G76: =F76-F70 -> 0.034807143
A77: 23833 | B77: 1.79034 | D77: =MEDIAN(B17:B77) -> 1.84183 | E77: =AVERAGE(B71:B77) -> 1.7666971 | F77: =E77-D77 -> -0.075132857 | G77: =F77-F71 -> 0.035727143
A78: 23863 | B78: 1.81059 | D78: =MEDIAN(B18:B78) -> 1.83958 | E78: =AVERAGE(B72:B78) -> 1.7728386 | F78: =E78-D78 -> -0.066741429 | G78: =F78-F72 -> 0.041627143
A79: 23894 | B79: 1.85806 | D79: =MEDIAN(B19:B79) -> 1.83958 | E79: =AVERAGE(B73:B79) -> 1.7852743 | F79: =E79-D79 -> -0.054305714 | G79: =F79-F73 -> 0.047015714
... A809: 46113 | B809: 2.31351 | D809: =MEDIAN(B749:B809) -> 2.12872 | E809: =AVERAGE(B803:B809) -> 2.0923371 | F809: =E809-D809 -> -0.036382857 | G809: =F809-F803 -> 0.090114286
